<?xml version="1.0" encoding="utf-8"?>
<!-- This URDF was automatically created by SolidWorks to URDF Exporter! Originally created by Stephen Brawner (brawner@gmail.com) 
     Commit Version: 1.6.0-1-g15f4949  Build Version: 1.6.7594.29634
     For more information, please see http://wiki.ros.org/sw_urdf_exporter -->
<robot
  name="mobile_robot">
  <link
    name = "dummy_link">
  </link>
  
  <link
    name="base_link">
    <inertial>
      <origin
        xyz="-0.11001 0.14012 0.011651"
        rpy="0 0 0" />
      <mass
        value="96.8" />
      <inertia
        ixx="2.4426"
        ixy="-0.18931"
        ixz="-0.0011354"
        iyy="7.0227"
        iyz="0.0018821"
        izz="5.7036" />
    </inertial>
    <visual>
      <origin
        xyz="0 0 0"
        rpy="0 0 0" />
      <geometry>
        <mesh
          filename="package://mobile_robot/meshes/base_link.STL" />
      </geometry>
      <material
        name="">
        <color
          rgba="0 1 1 1" />
      </material>
    </visual>
    <collision>
      <origin
        xyz="0 0 0"
        rpy="0 0 0" />
      <geometry>
        <mesh
          filename="package://mobile_robot/meshes/base_link.STL" />
      </geometry>
    </collision>
  </link>
  
  <joint
    name = "dummy_joint"
    type ="fixed">
    <parent
    link = "dummy_link"/>
    <child
    link = "base_link"/>
  </joint>
  
  <link
    name="rear_axle">
    <inertial>
      <origin
        xyz="0.011801 5.5511E-17 1.9429E-16"
        rpy="0 0 0" />
      <mass
        value="3.9541" />
      <inertia
        ixx="0.019882"
        ixy="-1.5458E-17"
        ixz="-7.8632E-17"
        iyy="0.38792"
        iyz="-1.0334E-33"
        izz="0.38792" />
    </inertial>
    <visual>
      <origin
        xyz="0 0 0"
        rpy="0 0 0" />
      <geometry>
        <mesh
          filename="package://mobile_robot/meshes/rear_axle.STL" />
      </geometry>
      <material
        name="">
        <color
          rgba="0.79216 0.81961 0.93333 1" />
      </material>
    </visual>
    <collision>
      <origin
        xyz="0 0 0"
        rpy="0 0 0" />
      <geometry>
        <mesh
          filename="package://mobile_robot/meshes/rear_axle.STL" />
      </geometry>
    </collision>
  </link>
  <joint
    name="joint_ra"
    type="continuous">
    <origin
      xyz="-0.18897 0 0.0508"
      rpy="2.0145 0 -1.5708" />
    <parent
      link="base_link" />
    <child
      link="rear_axle" />
    <axis
      xyz="1 0 0" />
  </joint>
  <link
    name="front_axle">
    <inertial>
      <origin
        xyz="9.8879E-17 0.050363 3.4781E-10"
        rpy="0 0 0" />
      <mass
        value="1.1528" />
      <inertia
        ixx="0.0028829"
        ixy="-4.7973E-18"
        ixz="6.5563E-11"
        iyy="0.039949"
        iyz="9.6064E-11"
        izz="0.042604" />
    </inertial>
    <visual>
      <origin
        xyz="0 0 0"
        rpy="0 0 0" />
      <geometry>
        <mesh
          filename="package://mobile_robot/meshes/front_axle.STL" />
      </geometry>
      <material
        name="">
        <color
          rgba="0.79216 0.81961 0.93333 1" />
      </material>
    </visual>
    <collision>
      <origin
        xyz="0 0 0"
        rpy="0 0 0" />
      <geometry>
        <mesh
          filename="package://mobile_robot/meshes/front_axle.STL" />
      </geometry>
    </collision>
  </link>
  <joint
    name="joint_fa"
    type="revolute">
    <origin
      xyz="0.3209 -0.011801 0.0254"
      rpy="1.5708 0 1.5766" />
    <parent
      link="base_link" />
    <child
      link="front_axle" />
    <axis
      xyz="0 1 0" />
    <limit
      lower= "-0.262"
      upper= "0.262"
      effort = "200"
      velocity= "10" />
  </joint>
  <link
    name="front_wheel1">
    <inertial>
      <origin
        xyz="-0.039311 -2.0123E-16 -6.6613E-16"
        rpy="0 0 0" />
      <mass
        value="1.5322" />
      <inertia
        ixx="0.009825"
        ixy="3.4607E-18"
        ixz="7.0416E-17"
        iyy="0.0056396"
        iyz="5.1069E-20"
        izz="0.0056396" />
    </inertial>
    <visual>
      <origin
        xyz="0 0 0"
        rpy="0 0 0" />
      <geometry>
        <mesh
          filename="package://mobile_robot/meshes/front_wheel1.STL" />
      </geometry>
      <material
        name="">
        <color
          rgba="0.79216 0.81961 0.93333 1" />
      </material>
    </visual>
    <collision>
      <origin
        xyz="0 0 0"
        rpy="0 0 0" />
      <geometry>
        <mesh
          filename="package://mobile_robot/meshes/front_wheel1.STL" />
      </geometry>
    </collision>
  </link>
  <joint
    name="joint_fw1"
    type="continuous">
    <origin
      xyz="-0.28962 0.0254 0"
      rpy="-0.020659 0 0" />
    <parent
      link="front_axle" />
    <child
      link="front_wheel1" />
    <axis
      xyz="1 0 0" />
  </joint>
  <link
    name="front_wheel2">
    <inertial>
      <origin
        xyz="0.039775 -1.6653E-16 -1.1102E-16"
        rpy="0 0 0" />
      <mass
        value="1.5322" />
      <inertia
        ixx="0.009825"
        ixy="3.051E-18"
        ixz="1.6432E-19"
        iyy="0.0056396"
        iyz="-9.4324E-19"
        izz="0.0056396" />
    </inertial>
    <visual>
      <origin
        xyz="0 0 0"
        rpy="0 0 0" />
      <geometry>
        <mesh
          filename="package://mobile_robot/meshes/front_wheel2.STL" />
      </geometry>
      <material
        name="">
        <color
          rgba="0.79216 0.81961 0.93333 1" />
      </material>
    </visual>
    <collision>
      <origin
        xyz="0 0 0"
        rpy="0 0 0" />
      <geometry>
        <mesh
          filename="package://mobile_robot/meshes/front_wheel2.STL" />
      </geometry>
    </collision>
  </link>
  <joint
    name="joint_fw2"
    type="continuous">
    <origin
      xyz="0.28915 0.0254 0"
      rpy="-0.72236 0 0" />
    <parent
      link="front_axle" />
    <child
      link="front_wheel2" />
    <axis
      xyz="1 0 0" />
  </joint>

<gazebo reference = "base_link">
  <material>Gazebo/Turquoise</material>
</gazebo>
<gazebo reference = "rear_axle">
  <material>Gazebo/WhiteGlow</material>
</gazebo>
<gazebo reference = "front_axle">
  <material>Gazebo/WhiteGlow</material>
</gazebo>
<gazebo reference = "front_wheel1">
  <material>Gazebo/WhiteGlow</material>
</gazebo>
<gazebo reference = "front_wheel2">
  <material>Gazebo/WhiteGlow</material>
</gazebo>
<transmission name="fa_trans">
  <type>SimpleTransmission</type>
  <joint name="joint_fa">
    <hardwareInterface>hardware_interface/EffortJointInterface</hardwareInterface>
  </joint>
  <actuator name="motor_fa">
    <mechanicalReduction>50</mechanicalReduction>
    <hardwareInterface>hardware_interface/EffortJointInterface</hardwareInterface>
  </actuator>
</transmission>
<transmission name="ra_trans">
  <type>SimpleTransmission</type>
  <joint name="joint_ra">
    <hardwareInterface>hardware_interface/VelocityJointInterface</hardwareInterface>
  </joint>
  <actuator name="motor_ra">
    <mechanicalReduction>50</mechanicalReduction>
    <hardwareInterface>hardware_interface/VelocityJointInterface</hardwareInterface>
  </actuator>
</transmission>
</robot>
